Workbook

Sheet SE1000 (черный лист)
M1: Курс Eвро | N1: 72.57 | AE1: 0.95 | AH1: скидка
B2: Провенто | E2: УЗОЛА | H2: Rittal | O2: DKS (CE) | U2: DKS (ST) | AA2: IPEX
B3: Артикул | C3: Прайсовая цена, руб с НДС | D3: Цена со стандартной скидкой для щитовиков 25% | E3: Артикул | F3: Наименование | G3: Прайсовая цена, руб с НДС | H3: Артикул | I3: Наименование | J3: Прайсовая цена Rittal, евро с НДС | K3: Прайсовая цена Rittal, руб с НДС | L3: наличие в Казани | M3: цена ЭТМ со скидкой | N3: Прайс ЭТМ (розница) | O3: Артикул | P3: Наименование | Q3: Прайсовая цена ДКС, руб с НДС | R3: наличие в Казани | S3: цена ЭТМ со скидкой | T3: Прайс ЭТМ (розница) | U3: Артикул | V3: Наименование | W3: Прайсовая цена ДКС, руб с НДС | X3: наличие в Казани | Y3: цена ЭТМ со скидкой | Z3: Прайс ЭТМ (розница) | AA3: А, мм. | AB3: В, мм. | AC3: С, мм. | AD3: Артикул | AE3: цена со скидкой 5% от DKC (ST)-24 столб | AF3: Прайсовая цена | AH3: сумма со скидкой на объем складского запаса | AL3: Себестоимость
B4: MES 30.20.15 | C4: 3055 | D4: =C4*0.75 -> 2291.25 | E4: U7521302015 | F4: Корпус UC2 30.20.15 IP66 USOLA | G4: 2644 | H4: 1035500 | I4: AE Шкаф RAL7035, с МП, 200x300x155mm | J4: 46.49 | K4: =J4*$N$1 -> 3373.7793 | M4: 3,126.06 | N4: 3,866.00 | O4: R5CE0231 | P4: Навесной шкаф CE, 200 х 300 х 150мм, IP66 | Q4: 4682.79 | R4: 0 | S4: 3868.04 | T4: 5012 | U4: R5ST0231 | V4: Корпус сварной навесной серии ST с М/П Размер: 200 x 300 x 150 мм (В х Ш х Г) | W4: 2814.02 | X4: 19 | Y4: 2324.41 | Z4: 3012 | AA4: 300 | AB4: 200 | AC4: 150 | AD4: SЕ1001 | AE4: =Y4*$AE$1 -> 2208.1895 | AF4: =AE4/0.75 -> 2944.2527 | AG4: =ROUND(AF4,0) -> 2944 | AH4: =X47*AE4 -> 13249.137 | AI4: 1 | AJ4: =2*(AA4*AB4+AB4*AC4+AA4*AC4)/1000000 -> 0.27 | AK4: =AE4/AJ4 -> 8178.4796 | AL4: 3541.4
D5: =C5*0.75 -> 0 | K5: =J5*$N$1 -> 0 | O5: R5CE0391 | P5: Навесной шкаф CE, 300 x 250 x 150мм, IP66 | Q5: 4838.95 | R5: 0 | S5: 3997.03 | T5: 5179 | U5: R5ST0391 | V5: Корпус сварной навесной серии ST с М/П Размер: 300 x 250 x 150 мм (В х Ш х Г) | W5: 2899.45 | X5: 7 | Y5: 2394.98 | Z5: 3103 | AA5: 300 | AB5: 250 | AC5: 150 | AD5: SE1002 | AE5: =Y5*$AE$1 -> 2275.231 | AF5: =AE5/0.75 -> 3033.6413 | AG5: =ROUND(AF5,0) -> 3034 | AH5: =X4*AE5 -> 43229.389 | AI5: 1 | AJ5: =2*(AA5*AB5+AB5*AC5+AA5*AC5)/1000000 -> 0.315 | AK5: =AE5/AJ5 -> 7222.9556
B6: MES 30.30.15 | C6: 3433 | D6: =C6*0.75 -> 2574.75 | E6: U7521303015 | F6: Корпус UC2 30.30.15 IP66 USOLA | G6: 2970 | H6: 1036500 | I6: AE Шкаф RAL7035 с МП, 300x300x155mm | J6: 59.22 | K6: =J6*$N$1 -> 4297.5954 | M6: 3,983.30 | N6: 4,926.00 | O6: R5CE0331 | P6: Навесной шкаф CE, 300 x 300 x 150мм, IP66 | Q6: 5205.09 | R6: 0 | S6: 4299.47 | T6: 5571 | U6: R5ST0331 | V6: Корпус сварной навесной серии ST с М/П Размер: 300 x 300 x 150 мм (В х Ш х Г) | W6: 3080.11 | X6: 55 | Y6: 2544.21 | Z6: 3296 | AA6: 300 | AB6: 300 | AC6: 150 | AD6: SE1003 | AE6: =Y6*$AE$1 -> 2416.9995 | AF6: =AE6/0.75 -> 3222.666 | AG6: =ROUND(AF6,0) -> 3223 | AH6: =X5*AE6 -> 16918.997 | AI6: 1 | AJ6: =2*(AA6*AB6+AB6*AC6+AA6*AC6)/1000000 -> 0.36 | AK6: =AE6/AJ6 -> 6713.8875
B7: MES 30.40.15 | C7: 3487 | D7: =C7*0.75 -> 2615.25 | E7: U7521304015 | F7: Корпус UC2 30.40.15 IP66 USOLA | G7: 3264 | H7: 1030500 | I7: AE Шкаф RAL7035, с МП, 380x300x155mm | J7: 57 | K7: =J7*$N$1 -> 4136.49 | M7: 3,833.29 | N7: 4,741.00 | O7: R5CE0341 | P7: Навесной шкаф CE, 300 x 400 x 150мм, IP66 | Q7: 5393.08 | R7: 0 | S7: 4454.75 | T7: 5772 | U7: R5ST0341 | V7: Корпус сварной навесной серии ST с М/П Размер: 300 x 400 x 150 мм (В х Ш х Г) | W7: 3182.84 | X7: 12 | Y7: 2629.06 | Z7: 3406 | AA7: 300 | AB7: 400 | AC7: 150 | AD7: SE1004 | AE7: =Y7*$AE$1 -> 2497.607 | AF7: =AE7/0.75 -> 3330.1427 | AG7: =ROUND(AF7,0) -> 3330 | AH7: =X6*AE7 -> 137368.39 | AI7: 1 | AJ7: =2*(AA7*AB7+AB7*AC7+AA7*AC7)/1000000 -> 0.45 | AK7: =AE7/AJ7 -> 5550.2378
D8: =C8*0.75 -> 0 | E8: U7521304020 | F8: Корпус UC2 30.40.20 IP66 USOLA | G8: 3078 | H8: 1031500 | I8: AE Шкаф RAL7035 с МП, 380x300x210mm | J8: 62.34 | K8: =J8*$N$1 -> 4524.0138 | L8: 0 | M8: 4,192.61 | N8: 5,185.00 | O8: R5CE0342 | P8: Навесной шкаф CE, 300 х 400 х 200мм, IP66 | Q8: 5901.76 | R8: 0 | S8: 4874.92 | T8: 6316 | U8: R5ST0342 | V8: Корпус сварной навесной серии ST с М/П Размер: 300 x 400 x 200 мм (В х Ш х Г) | W8: 3116.51 | X8: 18 | Y8: 2574.28 | Z8: 3335 | AA8: 300 | AB8: 400 | AC8: 200 | AD8: SE1005 | AE8: =Y8*$AE$1 -> 2445.566 | AF8: =AE8/0.75 -> 3260.7547 | AG8: =ROUND(AF8,0) -> 3261 | AH8: =X7*AE8 -> 29346.792 | AI8: 1 | AJ8: =2*(AA8*AB8+AB8*AC8+AA8*AC8)/1000000 -> 0.52 | AK8: =AE8/AJ8 -> 4703.0115
B9: MES 40.30.15 | C9: 3552 | D9: =C9*0.75 -> 2664 | E9: U7521403015 | F9: Корпус UC2 40.30.15 IP66 USOLA | G9: 3049 | K9: =J9*$N$1 -> 0 | O9: R5CE0431 | P9: Навесной шкаф CE, 400 x 300 x 150мм, IP66 | Q9: 5867.24 | R9: 0 | S9: 4846.41 | T9: 6279 | U9: R5ST0431 | V9: Корпус сварной навесной серии ST с М/П Размер: 400 x 300 x 150 мм (В х Ш х Г) | W9: 3285.53 | X9: 14 | Y9: 2713.88 | Z9: 3516 | AA9: 400 | AB9: 300 | AC9: 150 | AD9: SE1006 | AE9: =Y9*$AE$1 -> 2578.186 | AF9: =AE9/0.75 -> 3437.5813 | AG9: =ROUND(AF9,0) -> 3438 | AH9: =X8*AE9 -> 46407.348 | AI9: 1 | AJ9: =2*(AA9*AB9+AB9*AC9+AA9*AC9)/1000000 -> 0.45 | AK9: =AE9/AJ9 -> 5729.3022
B10: MES 40.30.21 | C10: 4028 | D10: =C10*0.75 -> 3021 | E10: U7521403020 | F10: Корпус UC2 40.30.20 IP66 USOLA | G10: 3457 | H10: 1034500 | I10: AE Шкаф RAL7035, с МП, 300x400x210mm | J10: 66.36 | K10: =J10*$N$1 -> 4815.7452 | L10: 4 | M10: 4,462.64 | N10: 5,519.00 | O10: R5CE0432 | P10: Навесной шкаф CE, 400 x 300 x 200мм, IP66 | Q10: 6187.28 | R10: 0 | S10: 5110.77 | T10: 6622 | U10: R5ST0432 | V10: Корпус сварной навесной серии ST с М/П Размер: 400 x 300 x 200 мм (В х Ш х Г) | W10: 3664.86 | X10: 38 | Y10: 3027.22 | Z10: 3922 | AA10: 400 | AB10: 300 | AC10: 200 | AD10: SE1007 | AE10: =Y10*$AE$1 -> 2875.859 | AF10: =AE10/0.75 -> 3834.4787 | AG10: =ROUND(AF10,0) -> 3834 | AH10: =X9*AE10 -> 40262.026 | AI10: 1 | AJ10: =2*(AA10*AB10+AB10*AC10+AA10*AC10)/1000000 -> 0.52 | AK10: =AE10/AJ10 -> 5530.4981
B11: MES 40.40.21 | C11: 4417 | D11: =C11*0.75 -> 3312.75 | E11: U7521404020 | F11: Корпус UC2 40.40.20 IP66 USOLA | G11: 3791 | H11: 1380500 | I11: AE Шкаф RAL7035, с МП, 380x380x210mm | J11: 66.08 | K11: =J11*$N$1 -> 4795.4256 | L11: 5 | M11: 4,444.07 | N11: 5,496.00 | O11: R5CE0442 | P11: Навесной шкаф CE, 400 x 400 x 200мм, IP66 | Q11: 6329.86 | R11: 0 | S11: 5228.54 | T11: 6774 | U11: R5ST0442 | V11: Корпус сварной навесной серии ST с М/П Размер: 400 x 400 x 200 мм (В х Ш х Г) | W11: 3712.47 | Y11: 3066.55 | Z11: 3973 | AA11: 400 | AB11: 400 | AC11: 200 | AD11: SE1008 | AE11: =Y11*$AE$1 -> 2913.2225 | AF11: =AE11/0.75 -> 3884.2967 | AG11: =ROUND(AF11,0) -> 3884 | AH11: =X10*AE11 -> 110702.45 | AI11: 1 | AJ11: =2*(AA11*AB11+AB11*AC11+AA11*AC11)/1000000 -> 0.64 | AK11: =AE11/AJ11 -> 4551.9102
B12: MES 40.60.21 | C12: 5296 | D12: =C12*0.75 -> 3972 | E12: U7521406020 | F12: Корпус UC2 40.60.20 IP66 USOLA | G12: 4547 | H12: 1039500 | I12: AE Шкаф RAL7035, с МП, 600x380x210mm | J12: 87.29 | K12: =J12*$N$1 -> 6334.6353 | L12: 1 | M12: 5,870.65 | N12: 7,260.00 | O12: R5CE0462 | P12: Навесной шкаф CE, 400 x 600 x 200мм, IP65 | Q12: 8646.76 | R12: 0 | S12: 7142.33 | T12: 9254 | U12: R5ST0462 | V12: Корпус сварной навесной серии ST с М/П Размер: 400 x 600 x 200 мм (В х Ш х Г) | W12: 5353.26 | X12: 20 | Y12: 4421.86 | Z12: 5729 | AA12: 400 | AB12: 600 | AC12: 200 | AD12: SE1009 | AE12: =Y12*$AE$1 -> 4200.767 | AF12: =AE12/0.75 -> 5601.0227 | AG12: =ROUND(AF12,0) -> 5601 | AH12: =X11*AE12 -> 0 | AI12: 1 | AJ12: =2*(AA12*AB12+AB12*AC12+AA12*AC12)/1000000 -> 0.88 | AK12: =AE12/AJ12 -> 4773.5989
B13: MES 50.30.21 | C13: 4782 | D13: =C13*0.75 -> 3586.5 | E13: U7521503015 | F13: Корпус UC2 50.30.15 IP66 USOLA | G13: 4074 | K13: =J13*$N$1 -> 0 | O13: R5CE0531 | P13: Навесной шкаф CE, 500 x 300 x 150мм, IP66 | Q13: 7038.49 | R13: 0 | S13: 5813.87 | T13: 7533 | U13: R5ST0531 | V13: Корпус сварной навесной серии ST с М/П Размер: 500 x 300 x 150 мм (В х Ш х Г) | W13: 4205.05 | X13: 11 | Y13: 3473.42 | Z13: 4500 | AA13: 500 | AB13: 300 | AC13: 150 | AD13: SE1010 | AE13: =Y13*$AE$1 -> 3299.749 | AF13: =AE13/0.75 -> 4399.6653 | AG13: =ROUND(AF13,0) -> 4400 | AH13: =X12*AE13 -> 65994.98 | AI13: 1 | AJ13: =2*(AA13*AB13+AB13*AC13+AA13*AC13)/1000000 -> 0.54 | AK13: =AE13/AJ13 -> 6110.6463
D14: =C14*0.75 -> 0 | E14: U7521503020 | F14: Корпус UC2 50.30.20 IP66 USOLA | G14: 4106 | K14: =J14*$N$1 -> 0 | O14: R5CE0532 | P14: Навесной шкаф CE, 500 x 300 x 200мм, IP66 | Q14: 7258.41 | R14: 0 | S14: 5995.53 | T14: 7768 | U14: R5ST0532 | V14: Корпус сварной навесной серии ST с М/П Размер: 500 x 300 x 200 мм (В х Ш х Г) | W14: 4570.97 | X14: 10 | Y14: 3775.67 | Z14: 4892 | AA14: 500 | AB14: 300 | AC14: 200 | AD14: SE1011 | AE14: =Y14*$AE$1 -> 3586.8865 | AF14: =AE14/0.75 -> 4782.5153 | AG14: =ROUND(AF14,0) -> 4783 | AH14: =X13*AE14 -> 39455.751 | AI14: 1 | AJ14: =2*(AA14*AB14+AB14*AC14+AA14*AC14)/1000000 -> 0.62 | AK14: =AE14/AJ14 -> 5785.3008
B15: MES 50.40.21 | C15: 5078 | D15: =C15*0.75 -> 3808.5 | E15: U7521504020 | F15: Корпус UC2 50.40.20 IP66 USOLA | G15: 4360 | H15: 1045500 | I15: AE Шкаф RAL7035 с МП, 400x500x210mm | J15: 76.4 | K15: =J15*$N$1 -> 5544.348 | L15: 2 | M15: 5,138.43 | N15: 6,355.00 | O15: R5CE0542 | P15: Навесной шкаф CE, 500 x 400 x 200мм, IP66 | Q15: 7355.23 | R15: 0 | S15: 6075.5 | T15: 7872 | U15: R5ST0542 | V15: Корпус сварной навесной серии ST с М/П Размер: 500 x 400 x 200 мм (В х Ш х Г) | W15: 4645.98 | X15: 22 | Y15: 3837.63 | Z15: 4972 | AA15: 500 | AB15: 400 | AC15: 200 | AD15: SE1012 | AE15: =Y15*$AE$1 -> 3645.7485 | AF15: =AE15/0.75 -> 4860.998 | AG15: =ROUND(AF15,0) -> 4861 | AH15: =X14*AE15 -> 36457.485 | AI15: 1 | AJ15: =2*(AA15*AB15+AB15*AC15+AA15*AC15)/1000000 -> 0.76 | AK15: =AE15/AJ15 -> 4797.0375
B16: MES 50.50.21 | C16: 5625 | D16: =C16*0.75 -> 4218.75 | E16: U7521505020 | F16: Корпус UC2 50.50.20 IP66 USOLA | G16: 4829 | H16: 1050500 | I16: AE Шкаф RAL7035 с МП, 500x500x210mm | J16: 92.85 | K16: =J16*$N$1 -> 6738.1245 | L16: 0 | M16: 6,244.97 | N16: 7,723.00 | O16: R5CE0552 | P16: Навесной шкаф CE, 500 x 500 x 200мм, IP65 | Q16: 9198.97 | R16: 0 | S16: 7598.46 | T16: 9845 | U16: R5ST0552 | V16: Корпус сварной навесной серии ST с М/П Размер: 500 x 500 x 200 мм (В х Ш х Г) | W16: 5304.16 | X16: 63 | Y16: 4381.3 | Z16: 5677 | AA16: 500 | AB16: 500 | AC16: 200 | AD16: SE1013 | AE16: =Y16*$AE$1 -> 4162.235 | AF16: =AE16/0.75 -> 5549.6467 | AG16: =ROUND(AF16,0) -> 5550 | AH16: =X15*AE16 -> 91569.17 | AI16: 1 | AJ16: =2*(AA16*AB16+AB16*AC16+AA16*AC16)/1000000 -> 0.9 | AK16: =AE16/AJ16 -> 4624.7056
D17: =C17*0.75 -> 0 | K17: =J17*$N$1 -> 0 | O17: R5CE0562 | P17: Навесной шкаф CE, 500 х 600 х 200мм, IP65 | Q17: 10557.71 | R17: 0 | S17: 8720.79 | T17: 11299 | U17: R5ST0562 | V17: Корпус сварной навесной серии ST с М/П Размер: 500 x 600 x 200 мм (В х Ш х Г) | W17: 5760.19 | X17: 0 | Y17: 4757.98 | Z17: 6165 | AA17: 500 | AB17: 600 | AC17: 200 | AD17: SE1014 | AE17: =Y17*$AE$1 -> 4520.081 | AF17: =AE17/0.75 -> 6026.7747 | AG17: =ROUND(AF17,0) -> 6027 | AH17: =X16*AE17 -> 284765.1 | AI17: 1 | AJ17: =2*(AA17*AB17+AB17*AC17+AA17*AC17)/1000000 -> 1.04 | AK17: =AE17/AJ17 -> 4346.2317
B18: MES 50.40.25 | C18: 5543 | D18: =C18*0.75 -> 4157.25 | E18: U7521504025 | F18: Корпус UC2 50.40.25 IP66 USOLA | G18: 4759 | K18: =J18*$N$1 -> 0 | O18: R5CE0549 | P18: Навесной шкаф CE, 500 x 400 x 250мм, IP65 | Q18: 8320.79 | R18: 0 | S18: 6873.08 | T18: 8905 | U18: R5ST0549 | V18: Корпус сварной навесной серии ST с М/П Размер: 500 x 400 x 250 мм (В х Ш х Г) | W18: 5135.3 | X18: 15 | Y18: 4241.82 | Z18: 5496 | AA18: 500 | AB18: 400 | AC18: 250 | AD18: SE1015 | AE18: =Y18*$AE$1 -> 4029.729 | AF18: =AE18/0.75 -> 5372.972 | AG18: =ROUND(AF18,0) -> 5373 | AH18: =X17*AE18 -> 0 | AI18: 1 | AJ18: =2*(AA18*AB18+AB18*AC18+AA18*AC18)/1000000 -> 0.85 | AK18: =AE18/AJ18 -> 4740.8576
D19: =C19*0.75 -> 0 | H19: 1350500 | I19: AE Шкаф RAL7035, с МП, 500x500x300mm | J19: 128.55 | K19: =J19*$N$1 -> 9328.8735 | L19: 0 | M19: 8,645.97 | N19: 10,692.00 | O19: R5CE0553 | P19: Навесной шкаф CE, 500 х 500 х 300мм, IP65 | Q19: 11877.42 | R19: 0 | S19: 9810.89 | T19: 12711 | U19: R5ST0553 | V19: Корпус сварной навесной серии ST с М/П Размер: 500 x 500 x 300 мм (В х Ш х Г) | W19: 6895.38 | X19: 25 | Y19: 5695.67 | Z19: 7380 | AA19: 500 | AB19: 500 | AC19: 300 | AD19: SE1016 | AE19: =Y19*$AE$1 -> 5410.8865 | AF19: =AE19/0.75 -> 7214.5153 | AG19: =ROUND(AF19,0) -> 7215 | AH19: =X18*AE19 -> 81163.298 | AI19: 1 | AJ19: =2*(AA19*AB19+AB19*AC19+AA19*AC19)/1000000 -> 1.1 | AK19: =AE19/AJ19 -> 4918.9877
D20: =C20*0.75 -> 0 | K20: =J20*$N$1 -> 0 | O20: R5CE0563 | P20: Навесной шкаф CE, 500 х 600 х 300мм, IP65 | Q20: 12453.46 | R20: 0 | S20: 10286.71 | T20: 13328 | U20: R5ST0563 | V20: Корпус сварной навесной серии ST с М/П Размер: 500 x 600 x 300 мм (В х Ш х Г) | W20: 7488.24 | X20: 2 | Y20: 6185.37 | Z20: 8014 | AA20: 500 | AB20: 600 | AC20: 300 | AD20: SE1017 | AE20: =Y20*$AE$1 -> 5876.1015 | AF20: =AE20/0.75 -> 7834.802 | AG20: =ROUND(AF20,0) -> 7835 | AH20: =X19*AE20 -> 146902.54 | AI20: 1 | AJ20: =2*(AA20*AB20+AB20*AC20+AA20*AC20)/1000000 -> 1.26 | AK20: =AE20/AJ20 -> 4663.5726
B21: MES 60.40.21 | C21: 5189 | D21: =C21*0.75 -> 3891.75 | E21: U7521604020 | F21: Корпус UC2 60.40.20 IP66 USOLA | G21: 4816 | H21: 1038500 | I21: AE Шкаф RAL7035, с МП, 380x600x210mm | J21: 81.06 | K21: =J21*$N$1 -> 5882.5242 | L21: 1 | M21: 5,452.04 | N21: 6,742.00 | O21: R5CE0642 | P21: Навесной шкаф CE, 600 x 400 x 200мм, IP65 | Q21: 8403.94 | R21: 0 | S21: 6941.75 | T21: 8994 | U21: R5ST0642 | V21: Корпус сварной навесной серии ST с М/П Размер: 600 x 400 x 200 мм (В х Ш х Г) | W21: 4912.7 | X21: 42 | Y21: 4057.95 | Z21: 5258 | AA21: 600 | AB21: 400 | AC21: 200 | AD21: SE1018 | AE21: =Y21*$AE$1 -> 3855.0525 | AF21: =AE21/0.75 -> 5140.07 | AG21: =ROUND(AF21,0) -> 5140 | AH21: =X20*AE21 -> 7710.105 | AI21: 1 | AJ21: =2*(AA21*AB21+AB21*AC21+AA21*AC21)/1000000 -> 0.88 | AK21: =AE21/AJ21 -> 4380.7415
D22: =C22*0.75 -> 0 | K22: =J22*$N$1 -> 0 | O22: R5CE0652 | P22: Навесной шкаф CE, 600 х 500 х 200мм,IP65 | Q22: 11327.53 | R22: 0 | S22: 9356.67 | T22: 12123 | U22: R5ST0652 | V22: Корпус сварной навесной серии ST с М/П Размер: 600 x 500 x 200 мм (В х Ш х Г) | W22: 6269.62 | X22: 16 | Y22: 5178.78 | Z22: 6710 | AA22: 600 | AB22: 500 | AC22: 200 | AD22: SE1019 | AE22: =Y22*$AE$1 -> 4919.841 | AF22: =AE22/0.75 -> 6559.788 | AG22: =ROUND(AF22,0) -> 6560 | AH22: =X21*AE22 -> 206633.32 | AI22: 1 | AJ22: =2*(AA22*AB22+AB22*AC22+AA22*AC22)/1000000 -> 1.04 | AK22: =AE22/AJ22 -> 4730.6163
B23: MES 60.40.25 | C23: 5847 | D23: =C23*0.75 -> 4385.25 | E23: U7521604025 | F23: Корпус UC2 60.40.25 IP66 USOLA | G23: 5020 | K23: =J23*$N$1 -> 0 | O23: R5CE0649 | P23: Навесной шкаф CE, 600 x 400 x 250мм, IP65 | Q23: 10298.46 | R23: 0 | S23: 8506.66 | T23: 11022 | U23: R5ST0649 | V23: Корпус сварной навесной серии ST с М/П Размер: 600 x 400 x 250 мм (В х Ш х Г) | W23: 5723.51 | X23: 101 | Y23: 4727.68 | Z23: 6125 | AA23: 600 | AB23: 400 | AC23: 250 | AD23: SE1020 | AE23: =Y23*$AE$1 -> 4491.296 | AF23: =AE23/0.75 -> 5988.3947 | AG23: =ROUND(AF23,0) -> 5988 | AH23: =X22*AE23 -> 71860.736 | AI23: 1 | AJ23: =2*(AA23*AB23+AB23*AC23+AA23*AC23)/1000000 -> 0.98 | AK23: =AE23/AJ23 -> 4582.9551 | AL23: 7084.8608
B24: MES 60.60.25 | C24: 7719 | D24: =C24*0.75 -> 5789.25 | E24: U7521606025 | F24: Корпус UC2 60.60.25 IP66 USOLA | G24: 6627 | H24: 1054500 | I24: AE Шкаф RAL7035 с МП, 600x600x250mm | J24: 135.9 | K24: =J24*$N$1 -> 9862.263 | L24: 0 | M24: 9,140.30 | N24: 11,304.00 | O24: R5CE0669 | P24: Навесной шкаф CE, 600 x 600 x 250мм, IP65 | Q24: 11910.4 | R24: 0 | S24: 9838.13 | T24: 12747 | U24: R5ST0669 | V24: Корпус сварной навесной серии ST с М/П Размер: 600 x 600 x 250 мм (В х Ш х Г) | W24: 6879.44 | X24: 26 | Y24: 5682.5 | Z24: 7363 | AA24: 600 | AB24: 600 | AC24: 250 | AD24: SE1021 | AE24: =Y24*$AE$1 -> 5398.375 | AF24: =AE24/0.75 -> 7197.8333 | AG24: =ROUND(AF24,0) -> 7198 | AH24: =X23*AE24 -> 545235.88 | AI24: 1 | AJ24: =2*(AA24*AB24+AB24*AC24+AA24*AC24)/1000000 -> 1.32 | AK24: =AE24/AJ24 -> 4089.678
D25: =C25*0.75 -> 0 | E25: U7521606040 | F25: Корпус UC2 60.60.40 IP66 USOLA | G25: 7729 | K25: =J25*$N$1 -> 0 | O25: R5CE0644 | P25: Навесной шкаф CE, 600 x 400 x 400мм, IP65 | Q25: 14167.6 | R25: 0 | S25: 11702.6 | T25: 15162 | U25: R5ST0644 | V25: Корпус сварной навесной серии ST с М/П Размер: 600 x 400 x 400 мм (В х Ш х Г) | W25: 7692.69 | X25: 4 | Y25: 6354.25 | Z25: 8233 | AA25: 600 | AB25: 400 | AC25: 400 | AD25: SE1022 | AE25: =Y25*$AE$1 -> 6036.5375 | AF25: =AE25/0.75 -> 8048.7167 | AG25: =ROUND(AF25,0) -> 8049 | AH25: =X24*AE25 -> 156949.97 | AI25: 1 | AJ25: =2*(AA25*AB25+AB25*AC25+AA25*AC25)/1000000 -> 1.28 | AK25: =AE25/AJ25 -> 4716.0449
D26: =C26*0.75 -> 0 | E26: U7521606035 | F26: Корпус UC2 60.60.35 IP66 USOLA | G26: 7392 | H26: 1360500 | I26: AE Шкаф RAL7035, с МП, 600x600x350mm | J26: 161.27 | K26: =J26*$N$1 -> 11703.364 | L26: 2 | M26: 10,846.93 | N26: 13,414.00 | O26: R5CE0664 | P26: Навесной шкаф CE, 600 x 600 x 400мм, IP65 | Q26: 18992.75 | R26: 0 | S26: 15688.23 | T26: 20326 | U26: R5ST0664 | V26: Корпус сварной навесной серии ST с М/П Размер: 600 x 600 x 400 мм (В х Ш х Г) | W26: 9708.69 | X26: 4 | Y26: 8019.49 | Z26: 10390 | AA26: 600 | AB26: 600 | AC26: 400 | AD26: SE1023 | AE26: =Y26*$AE$1 -> 7618.5155 | AF26: =AE26/0.75 -> 10158.021 | AG26: =ROUND(AF26,0) -> 10158 | AH26: =X25*AE26 -> 30474.062 | AI26: 1 | AJ26: =2*(AA26*AB26+AB26*AC26+AA26*AC26)/1000000 -> 1.68 | AK26: =AE26/AJ26 -> 4534.8307
B27: MES 70.50.21 | C27: 7262 | D27: =C27*0.75 -> 5446.5 | K27: =J27*$N$1 -> 0 | O27: R5CE0752 | P27: Навесной шкаф CE, 700 x 500 x 200мм, IP65 | Q27: 11934.99 | R27: 0 | S27: 9858.44 | T27: 12773 | U27: R5ST0752 | V27: Корпус сварной навесной серии ST с М/П Размер: 700 x 500 x 200 мм (В х Ш х Г) | W27: 6223.7 | X27: 26 | Y27: 5140.85 | Z27: 6661 | AA27: 700 | AB27: 500 | AC27: 200 | AD27: SE1024 | AE27: =Y27*$AE$1 -> 4883.8075 | AF27: =AE27/0.75 -> 6511.7433 | AG27: =ROUND(AF27,0) -> 6512 | AH27: =X26*AE27 -> 19535.23 | AI27: 1 | AJ27: =2*(AA27*AB27+AB27*AC27+AA27*AC27)/1000000 -> 1.18 | AK27: =AE27/AJ27 -> 4138.8199
B28: MES 70.50.25 | C28: 7744 | D28: =C28*0.75 -> 5808 | E28: U7521705025 | F28: Корпус UC2 70.50.25 IP66 USOLA | G28: 6454 | H28: 1057500 | I28: AE Шкаф RAL7035 с МП, 500x700x250mm | J28: 133.51 | K28: =J28*$N$1 -> 9688.8207 | L28: 1 | M28: 8,067.46 | N28: 11,105.00 | O28: R5CE0759 | P28: Навесной шкаф CE, 700 x 500 x 250мм, IP65 | Q28: 12160.19 | R28: 0 | S28: 10044.46 | T28: 13014 | U28: R5ST0759 | V28: Корпус сварной навесной серии ST с М/П Размер: 700 x 500 x 250 мм (В х Ш х Г) | W28: 6579.09 | X28: 24 | Y28: 5434.41 | Z28: 7041 | AA28: 700 | AB28: 500 | AC28: 250 | AD28: SE1025 | AE28: =Y28*$AE$1 -> 5162.6895 | AF28: =AE28/0.75 -> 6883.586 | AG28: =ROUND(AF28,0) -> 6884 | AH28: =X27*AE28 -> 134229.93 | AI28: 1 | AJ28: =2*(AA28*AB28+AB28*AC28+AA28*AC28)/1000000 -> 1.3 | AK28: =AE28/AJ28 -> 3971.2996
B29: MES 80.60.21 | C29: 8893 | D29: =C29*0.75 -> 6669.75 | K29: =J29*$N$1 -> 0 | O29: R5CE0862 | P29: Навесной шкаф CE, 800 х 600 х 200мм, IP65 | Q29: 12784.27 | R29: 0 | S29: 10559.96 | T29: 13682 | U29: R5ST0862 | V29: Корпус сварной навесной серии ST с М/П Размер: 800 x 600 x 200 мм (В х Ш х Г) | W29: 7830.34 | X29: 10 | Y29: 6467.96 | Z29: 8380 | AA29: 800 | AB29: 600 | AC29: 200 | AD29: SE1026 | AE29: =Y29*$AE$1 -> 6144.562 | AF29: =AE29/0.75 -> 8192.7493 | AG29: =ROUND(AF29,0) -> 8193 | AH29: =X28*AE29 -> 147469.49 | AI29: 1 | AJ29: =2*(AA29*AB29+AB29*AC29+AA29*AC29)/1000000 -> 1.52 | AK29: =AE29/AJ29 -> 4042.475
D30: =C30*0.75 -> 0 | K30: =J30*$N$1 -> 0 | O30: R5CE0882 | P30: Навесной шкаф CE, 800 х 800 х 200мм, IP65 | Q30: 16214.81 | R30: 0 | S30: 13393.63 | T30: 17353 | U30: R5ST0882 | V30: Корпус сварной навесной серии ST с М/П Размер: 800 x 800 x 200 мм (В х Ш х Г) | W30: 10724.15 | X30: 0 | Y30: 8858.27 | Z30: 11477 | AA30: 800 | AB30: 800 | AC30: 200 | AD30: SE1027 | AE30: =Y30*$AE$1 -> 8415.3565 | AF30: =AE30/0.75 -> 11220.475 | AG30: =ROUND(AF30,0) -> 11220 | AH30: =X29*AE30 -> 84153.565 | AI30: 1 | AJ30: =2*(AA30*AB30+AB30*AC30+AA30*AC30)/1000000 -> 1.92 | AK30: =AE30/AJ30 -> 4382.9982
B31: MES 80.60.25 | C31: 9453 | D31: =C31*0.75 -> 7089.75 | E31: U7521806025 | F31: Корпус UC2 80.60.25 IP66 USOLA | G31: 7877 | H31: 1058500 | I31: AE Шкаф RAL7035, с МП, 600x800x250mm | J31: 160.89 | K31: =J31*$N$1 -> 11675.787 | L31: 4 | M31: 10,821.92 | N31: 13,383.00 | O31: R5CE0869 | P31: Навесной шкаф CE, 800 x 600 x 250мм, IP65 | Q31: 13479.89 | R31: 0 | S31: 11134.55 | T31: 14427 | U31: R5ST0869 | V31: Корпус сварной навесной серии ST с М/П Размер: 800 x 600 x 250 мм (В х Ш х Г) | W31: 8026.13 | X31: 21 | Y31: 6629.68 | Z31: 8590 | AA31: 800 | AB31: 600 | AC31: 250 | AD31: SE1028 | AE31: =Y31*$AE$1 -> 6298.196 | AF31: =AE31/0.75 -> 8397.5947 | AG31: =ROUND(AF31,0) -> 8398 | AH31: =X30*AE31 -> 0 | AI31: 1 | AJ31: =2*(AA31*AB31+AB31*AC31+AA31*AC31)/1000000 -> 1.66 | AK31: =AE31/AJ31 -> 3794.094
B32: MES 80.60.30 | C32: 10058 | D32: =C32*0.75 -> 7543.5 | E32: U7521806030 | F32: Корпус UC2 80.60.30 IP66 USOLA | G32: 8382 | K32: =J32*$N$1 -> 0 | O32: R5CE0863 | P32: Навесной шкаф CE, 800 x 600 x 300мм, IP65 | Q32: 13455.55 | R32: 0 | S32: 11114.44 | T32: 14400 | U32: R5ST0863 | V32: Корпус сварной навесной серии ST с М/П Размер: 800 x 600 x 300 мм (В х Ш х Г) | W32: 8354.14 | X32: 39 | Y32: 6900.62 | Z32: 8941 | AA32: 800 | AB32: 600 | AC32: 300 | AD32: SE1029 | AE32: =Y32*$AE$1 -> 6555.589 | AF32: =AE32/0.75 -> 8740.7853 | AG32: =ROUND(AF32,0) -> 8741 | AH32: =X31*AE32 -> 137667.37 | AI32: 1 | AJ32: =2*(AA32*AB32+AB32*AC32+AA32*AC32)/1000000 -> 1.8 | AK32: =AE32/AJ32 -> 3641.9939
B33: MES 80.80.30 | C33: 12212 | D33: =C33*0.75 -> 9159 | K33: =J33*$N$1 -> 0 | O33: R5CE0883 | P33: Навесной шкаф CE, 800 x 800 x 300мм, IP65 | Q33: 17834.95 | R33: 0 | S33: 14731.88 | T33: 19087 | U33: R5ST0883 | V33: Корпус сварной навесной серии ST с М/П Размер: 800 x 800 x 300 мм (В х Ш х Г) | W33: 11973.1 | X33: 0 | Y33: 9889.92 | Z33: 12814 | AA33: 800 | AB33: 800 | AC33: 300 | AD33: SE1030 | AE33: =Y33*$AE$1 -> 9395.424 | AF33: =AE33/0.75 -> 12527.232 | AG33: =ROUND(AF33,0) -> 12527 | AH33: =X32*AE33 -> 366421.54 | AI33: 1 | AJ33: =2*(AA33*AB33+AB33*AC33+AA33*AC33)/1000000 -> 2.24 | AK33: =AE33/AJ33 -> 4194.3857
B34: MES 80.60.40 | C34: 13829 | D34: =C34*0.75 -> 10371.75 | K34: =J34*$N$1 -> 0 | O34: R5CE0864 | P34: Навесной шкаф CE, 800 x 600 x 400мм, IP65 | Q34: 22686.77 | R34: 0 | S34: 18739.54 | T34: 24280 | U34: R5ST0864 | V34: Корпус сварной навесной серии ST с М/П Размер: 800 x 600 x 400 мм (В х Ш х Г) | W34: 12076.86 | X34: 5 | Y34: 9975.63 | Z34: 12925 | AA34: 800 | AB34: 600 | AC34: 400 | AD34: SE1031 | AE34: =Y34*$AE$1 -> 9476.8485 | AF34: =AE34/0.75 -> 12635.798 | AG34: =ROUND(AF34,0) -> 12636 | AH34: =X33*AE34 -> 0 | AI34: 1 | AJ34: =2*(AA34*AB34+AB34*AC34+AA34*AC34)/1000000 -> 2.08 | AK34: =AE34/AJ34 -> 4556.1772
D35: =C35*0.75 -> 0 | E35: U7521808040 | F35: Корпус UC2 80.80.40 IP66 USOLA | G35: 10177 | K35: =J35*$N$1 -> 0 | O35: R5CE0884 | P35: Навесной шкаф CE, 800 x 800 x 400мм, IP65 | Q35: 25314.84 | R35: 0 | S35: 20910.36 | T35: 27093 | U35: R5ST0884 | V35: Корпус сварной навесной серии ST с М/П Размер: 800 x 800 x 400 мм (В х Ш х Г) | W35: 13753.09 | X35: 8 | Y35: 11360.21 | Z35: 14719 | AA35: 800 | AB35: 800 | AC35: 400 | AD35: SE1032 | AE35: =Y35*$AE$1 -> 10792.199 | AF35: =AE35/0.75 -> 14389.599 | AG35: =ROUND(AF35,0) -> 14390 | AH35: =X34*AE35 -> 53960.997 | AI35: 1 | AJ35: =2*(AA35*AB35+AB35*AC35+AA35*AC35)/1000000 -> 2.56 | AK35: =AE35/AJ35 -> 4215.7029
B36: MES 100.60.25 | C36: 10991 | D36: =C36*0.75 -> 8243.25 | E36: U7521106025 | F36: Корпус UC2 100.60.25 IP66 USOLA | G36: 9159 | H36: 1090500 | I36: AE Шкаф RAL7035, с МП, 600x1000x250mm | J36: 183.72 | K36: =J36*$N$1 -> 13332.56 | L36: 3 | M36: 12,357.09 | N36: 15,282.00 | O36: R5CE1069 | P36: Навесной шкаф CE, 1000 x 600 x 250мм, IP65 | Q36: 16232.42 | R36: 0 | S36: 13408.17 | T36: 17372 | U36: R5ST1069 | V36: Корпус сварной навесной серии ST с М/П Размер: 1000 x 600 x250 мм (В х Ш х Г) | W36: 10927.84 | X36: 1 | Y36: 9026.53 | Z36: 11695 | AA36: 1000 | AB36: 600 | AC36: 250 | AD36: SE1033 | AE36: =Y36*$AE$1 -> 8575.2035 | AF36: =AE36/0.75 -> 11433.605 | AG36: =ROUND(AF36,0) -> 11434 | AH36: =X35*AE36 -> 68601.628 | AI36: 1 | AJ36: =2*(AA36*AB36+AB36*AC36+AA36*AC36)/1000000 -> 2 | AK36: =AE36/AJ36 -> 4287.6017
B37: MES 100.60.30 | C37: 11752 | D37: =C37*0.75 -> 8814 | E37: U7521106030 | F37: Корпус UC2 100.60.30 IP66 USOLA | G37: 9794 | K37: =J37*$N$1 -> 0 | O37: R5CE1063 | P37: Навесной шкаф CE, 1000 x 600 x 300мм, IP65 | Q37: 17114.35 | R37: 0 | S37: 14136.66 | T37: 18316 | U37: R5ST1063 | V37: Корпус сварной навесной серии ST с М/П Размер: 1000 x 600 x300 мм (В х Ш х Г) | W37: 11952.9 | X37: 82 | Y37: 9873.24 | Z37: 12792 | AA37: 1000 | AB37: 600 | AC37: 300 | AD37: SE1034 | AE37: =Y37*$AE$1 -> 9379.578 | AF37: =AE37/0.75 -> 12506.104 | AG37: =ROUND(AF37,0) -> 12506 | AH37: =X36*AE37 -> 9379.578 | AI37: 1 | AJ37: =2*(AA37*AB37+AB37*AC37+AA37*AC37)/1000000 -> 2.16 | AK37: =AE37/AJ37 -> 4342.3972
B38: MES 100.80.30 | C38: 13916 | D38: =C38*0.75 -> 10437 | E38: U7521108030 | F38: Корпус UC2 100.80.30 IP66 USOLA | G38: 11597 | H38: 1180500 | I38: AE Шкаф RAL7035, с МП, 800x1000x300mm | J38: 210.95 | K38: =J38*$N$1 -> 15308.641 | L38: 1 | M38: 14,188.72 | N38: 17,547.00 | O38: R5CE1083 | P38: Навесной шкаф CE, 1000 x 800 x 300мм, IP65 | Q38: 20606.88 | R38: 1 | S38: 17021.52 | T38: 22054 | U38: R5ST1083 | V38: Корпус сварной навесной серии ST с М/П Размер: 1000 x 800 x300 мм (В х Ш х Г) | W38: 11866.58 | X38: 32 | Y38: 9801.93 | Z38: 12700 | AA38: 1000 | AB38: 800 | AC38: 300 | AD38: SE1035 | AE38: =Y38*$AE$1 -> 9311.8335 | AF38: =AE38/0.75 -> 12415.778 | AG38: =ROUND(AF38,0) -> 12416 | AH38: =X37*AE38 -> 763570.35 | AI38: 1 | AJ38: =2*(AA38*AB38+AB38*AC38+AA38*AC38)/1000000 -> 2.68 | AK38: =AE38/AJ38 -> 3474.5647
B39: MES 100.60.40 | C39: 16713 | D39: =C39*0.75 -> 12534.75 | E39: U7521106040 | F39: Корпус UC2 100.60.40 IP66 USOLA | G39: 13928 | K39: =J39*$N$1 -> 0 | O39: R5CE1064 | P39: Навесной шкаф CE, 1000 x 600 x 400мм, IP65 | Q39: 23523.85 | R39: 0 | S39: 19430.98 | T39: 25176 | U39: R5ST1064 | V39: Корпус сварной навесной серии ST с М/П Размер: 1000 x 600 x400 мм (В х Ш х Г) | W39: 14347.09 | X39: 7 | Y39: 11850.87 | Z39: 15355 | AA39: 1000 | AB39: 600 | AC39: 400 | AD39: SE1036 | AE39: =Y39*$AE$1 -> 11258.327 | AF39: =AE39/0.75 -> 15011.102 | AG39: =ROUND(AF39,0) -> 15011 | AH39: =X38*AE39 -> 360266.45 | AI39: 1 | AJ39: =2*(AA39*AB39+AB39*AC39+AA39*AC39)/1000000 -> 2.48 | AK39: =AE39/AJ39 -> 4539.6478
D40: =C40*0.75 -> 0 | K40: =J40*$N$1 -> 0 | O40: R5CE1084 | P40: Навесной шкаф CE, 1000 x 800 x 400мм, IP65 | Q40: 24928.39 | R40: 0 | S40: 20591.14 | T40: 26679 | U40: R5ST1084 | V40: Корпус сварной навесной серии ST с М/П Размер: 1000 x 800 x400 мм (В х Ш х Г) | W40: 15038 | X40: 4 | Y40: 12421.57 | Z40: 16094 | AA40: 1000 | AB40: 800 | AC40: 400 | AD40: SE1037 | AE40: =Y40*$AE$1 -> 11800.491 | AF40: =AE40/0.75 -> 15733.989 | AG40: =ROUND(AF40,0) -> 15734 | AH40: =X39*AE40 -> 82603.44 | AI40: 1 | AJ40: =2*(AA40*AB40+AB40*AC40+AA40*AC40)/1000000 -> 3.04 | AK40: =AE40/AJ40 -> 3881.7406
...

Sheet SE1100(черный лист)
H1: 420
G2: Прайсовая цена SE1000 | H2: Прайсовая цена SE1100
B3: SE1101.0231.1035 | C3: 300 | D3: 200 | E3: 150 | F3: IP67 | G3: 2944 | H3: =G3+$H$1 -> 3364
B4: SE1102.0391.1035 | C4: 300 | D4: 250 | E4: 150 | F4: IP67 | G4: 3034 | H4: =G4+$H$1 -> 3454
B5: SE1103.0331.1036 | C5: 300 | D5: 300 | E5: 150 | F5: IP67 | G5: 3223 | H5: =G5+$H$1 -> 3643
B6: SE1104.0341.1030 | C6: 300 | D6: 400 | E6: 150 | F6: IP67 | G6: 3330 | H6: =G6+$H$1 -> 3750
B7: SE1105.0342.1031 | C7: 300 | D7: 400 | E7: 200 | F7: IP67 | G7: 3261 | H7: =G7+$H$1 -> 3681
B8: SE1106.0431.1034 | C8: 400 | D8: 300 | E8: 150 | F8: IP67 | G8: 3438 | H8: =G8+$H$1 -> 3858
B9: SE1107.0432.1034 | C9: 400 | D9: 300 | E9: 200 | F9: IP67 | G9: 3834 | H9: =G9+$H$1 -> 4254
B10: SE1108.0442.1380 | C10: 400 | D10: 400 | E10: 200 | F10: IP67 | G10: 3884 | H10: =G10+$H$1 -> 4304
B11: SE1109.0462.1039 | C11: 400 | D11: 600 | E11: 200 | F11: IP67 | G11: 5601 | H11: =G11+$H$1 -> 6021
B12: SE1110.0531.1045 | C12: 500 | D12: 300 | E12: 150 | F12: IP67 | G12: 4400 | H12: =G12+$H$1 -> 4820
B13: SE1111.0532.1045 | C13: 500 | D13: 300 | E13: 200 | F13: IP67 | G13: 4783 | H13: =G13+$H$1 -> 5203
B14: SE1112.0542.1045 | C14: 500 | D14: 400 | E14: 200 | F14: IP67 | G14: 4861 | H14: =G14+$H$1 -> 5281
... B46: SE1144.1483.1280 | C46: 1400 | D46: 800 | E46: 300 | F46: IP66 | G46: 22390 | H46: =G46+$H$1 -> 22810

Sheet SF1000 и SF1100
H1: 2500
F2: площадь | G2: цена на SE1000 | H2: Прайсовая цена на SF1000 | I2: Цена со скидкой SF100
B3: 300 | C3: 200 | D3: 150 | E3: SF1001.0231.1035 | F3: 0.27 | G3: 2944 | H3: =F3*$H$1+G3 -> 3619 | I3: =H3*0.75 -> 2714.25 | J3: 2208.1895
B4: 300 | C4: 250 | D4: 150 | E4: SF1002.0391.1035 | F4: 0.315 | G4: 3034 | H4: =F4*$H$1+G4 -> 3821.5 | I4: =H4*0.75 -> 2866.125 | J4: 2275.231
B5: 300 | C5: 300 | D5: 150 | E5: SF1003.0331.1036 | F5: 0.36 | G5: 3223 | H5: =F5*$H$1+G5 -> 4123 | I5: =H5*0.75 -> 3092.25 | J5: 2416.9995
B6: 300 | C6: 400 | D6: 150 | E6: SF1004.0341.1030 | F6: 0.45 | G6: 3330 | H6: =F6*$H$1+G6 -> 4455 | I6: =H6*0.75 -> 3341.25 | J6: 2497.607
B7: 300 | C7: 400 | D7: 200 | E7: SF1005.0342.1031 | F7: 0.52 | G7: 3261 | H7: =F7*$H$1+G7 -> 4561 | I7: =H7*0.75 -> 3420.75 | J7: 2445.566
B8: 400 | C8: 300 | D8: 150 | E8: SF1006.0431.1034 | F8: 0.45 | G8: 3438 | H8: =F8*$H$1+G8 -> 4563 | I8: =H8*0.75 -> 3422.25 | J8: 2578.186
B9: 400 | C9: 300 | D9: 200 | E9: SF1007.0432.1034 | F9: 0.52 | G9: 3834 | H9: =F9*$H$1+G9 -> 5134 | I9: =H9*0.75 -> 3850.5 | J9: 2875.859
B10: 400 | C10: 400 | D10: 200 | E10: SF1008.0442.1380 | F10: 0.64 | G10: 3884 | H10: =F10*$H$1+G10 -> 5484 | I10: =H10*0.75 -> 4113 | J10: 2913.2225
B11: 400 | C11: 600 | D11: 200 | E11: SF1009.0462.1039 | F11: 0.88 | G11: 5601 | H11: =F11*$H$1+G11 -> 7801 | I11: =H11*0.75 -> 5850.75 | J11: 4200.767
B12: 500 | C12: 300 | D12: 150 | E12: SF1010.0531.1045 | F12: 0.54 | G12: 4400 | H12: =F12*$H$1+G12 -> 5750 | I12: =H12*0.75 -> 4312.5 | J12: 3299.749
B13: 500 | C13: 300 | D13: 200 | E13: SF1011.0532.1045 | F13: 0.62 | G13: 4783 | H13: =F13*$H$1+G13 -> 6333 | I13: =H13*0.75 -> 4749.75 | J13: 3586.8865
B14: 500 | C14: 400 | D14: 200 | E14: SF1012.0542.1045 | F14: 0.76 | G14: 4861 | H14: =F14*$H$1+G14 -> 6761 | I14: =H14*0.75 -> 5070.75 | J14: 3645.7485
... B46: 1400 | C46: 800 | D46: 300 | E46: SF1044.1483.1280 | F46: 3.56 | G46: 22390 | H46: =F46*$H$1+G46 -> 31290 | I46: =H46*0.75 -> 23467.5 | J46: 16792.247
E47: SF1101.0231.1035 | F47: 0.27 | G47: 3364 | H47: =F47*$H$1+G47 -> 4039
E48: SF1102.0391.1035 | F48: 0.315 | G48: 3454 | H48: =F48*$H$1+G48 -> 4241.5
E49: SF1103.0331.1036 | F49: 0.36 | G49: 3643 | H49: =F49*$H$1+G49 -> 4543
E50: SF1104.0341.1030 | F50: 0.45 | G50: 3750 | H50: =F50*$H$1+G50 -> 4875
E51: SF1105.0342.1031 | F51: 0.52 | G51: 3681 | H51: =F51*$H$1+G51 -> 4981
E52: SF1106.0431.1034 | F52: 0.45 | G52: 3858 | H52: =F52*$H$1+G52 -> 4983
E53: SF1107.0432.1034 | F53: 0.52 | G53: 4254 | H53: =F53*$H$1+G53 -> 5554
E54: SF1108.0442.1380 | F54: 0.64 | G54: 4304 | H54: =F54*$H$1+G54 -> 5904
E55: SF1109.0462.1039 | F55: 0.88 | G55: 6021 | H55: =F55*$H$1+G55 -> 8221
E56: SF1110.0531.1045 | F56: 0.54 | G56: 4820 | H56: =F56*$H$1+G56 -> 6170
E57: SF1111.0532.1045 | F57: 0.62 | G57: 5203 | H57: =F57*$H$1+G57 -> 6753
E58: SF1112.0542.1045 | F58: 0.76 | G58: 5281 | H58: =F58*$H$1+G58 -> 7181
... E90: SF1144.1483.1280 | F90: 3.56 | G90: 22810 | H90: =F90*$H$1+G90 -> 31710

Sheet SE2000 (нерж304)
J1: 1.3 | K1: 0.95 | N1: Провенто
B2: IPEX | H2: Площадь поверхности | I2: Себестоимость | J2: Наша цена с наценкой от себестоимости | K2: Наша цена от провенто | L2: Прайсовая цена | N2: артикул | O2: прайсовая цена | P2: цена провенто со скидкой 25% | Q2: Стоимость м2 | R2: вычисленная стоимостьм2 | S2: Вычисленная цена сос скидкой | T2: УЗОЛА | V2: Rittal | Y2: 72.57 | Z2: Цена ЭТМ со Скидкой | AA2: Цена ЭТМ розница | AD2: DKS | AF2: Цена ЭТМ со Скидкой | AG2: Цена ЭТМ розница
B3: 300 | C3: 200 | D3: 150 | E3: IP67 | F3: 1 | G3: SЕ2001 | H3: =2*(B3*C3+C3*D3+B3*D3)/1000000 -> 0.27 | I3: 5707.0047 | J3: =I3*$J$1 -> 7419.1061 | K3: =S3*$K$1 -> 8269.275 | L3: =K3/0.75 -> 11025.7 | M3: =ROUND(L3,0) -> 11026 | N3: SES 30.20.15 | O3: 11606 | P3: =O3*0.75 -> 8704.5 | Q3: =P3/H3 -> 32238.889 | R3: 32238.889 | S3: =R3*H3 -> 8704.5 | T3: Корпус UC2 30.20.15 из нержавеющей стали IP66 USOLA | U3: 8690 | V3: 1002600 | W3: AE Шкаф, нерж.сталь с МП 200x300x155mm | X3: 172.1 | Y3: =X3*$Y$2 -> 12489.297 | Z3: 11,575.58 | AA3: 14,315.00
B4: 300 | C4: 250 | D4: 150 | E4: IP67 | F4: 1 | G4: SE2002 | H4: =2*(B4*C4+C4*D4+B4*D4)/1000000 -> 0.315 | J4: =I4*$J$1 -> 0 | K4: =S4*$K$1 -> 6594.9559 | L4: =K4/0.75 -> 8793.2746 | M4: =ROUND(L4,0) -> 8793 | P4: =O4*0.75 -> 0 | Q4: =P4/H4 -> 0 | R4: 22038.282 | S4: =R4*H4 -> 6942.0589 | Y4: =X4*$Y$2 -> 0 | AC4: R5CEB03911 | AD4: Навесной шкаф CE из нержавеющей стали (AISI 304), 300 x 250x 150мм, без фланца | AE4: 16614.36 | AF4: 11,630.22 | AG4: 15,069.00
B5: 300 | C5: 300 | D5: 150 | E5: IP67 | F5: 1 | G5: SE2003 | H5: =2*(B5*C5+C5*D5+B5*D5)/1000000 -> 0.36 | J5: =I5*$J$1 -> 0 | K5: =S5*$K$1 -> 6873.0188 | L5: =K5/0.75 -> 9164.025 | M5: =ROUND(L5,0) -> 9164 | P5: =O5*0.75 -> 0 | Q5: =P5/H5 -> 0 | R5: 20096.546 | S5: =R5*H5 -> 7234.7566 | Y5: =X5*$Y$2 -> 0 | AC5: R5CEB03311 | AD5: Навесной шкаф CE из нержавеющей стали (AISI 304), 300 x 300x 150мм, без фланца | AE5: 17311.45 | AF5: 12,118.19 | AG5: 15,701.00
B6: 300 | C6: 400 | D6: 150 | E6: IP67 | F6: 1 | G6: SE2004 | H6: =2*(B6*C6+C6*D6+B6*D6)/1000000 -> 0.45 | J6: =I6*$J$1 -> 0 | K6: =S6*$K$1 -> 9298.125 | L6: =K6/0.75 -> 12397.5 | M6: =ROUND(L6,0) -> 12398 | N6: SES 30.40.15 | O6: 13050 | P6: =O6*0.75 -> 9787.5 | Q6: =P6/H6 -> 21750 | R6: 21750 | S6: =R6*H6 -> 9787.5 | T6: Корпус UC2 30.40.15 из нержавеющей стали IP66 USOLA | U6: 9790 | V6: 1004600 | W6: AE Шкаф, нерж.сталь с МП 380x300x155mm | X6: 199.21 | Y6: =X6*$Y$2 -> 14456.67 | Z6: 13,398.64 | AA6: 16,570.00 | AC6: R5CEB03411 | AD6: Навесной шкаф CE из нержавеющей стали (AISI 304), 300 x 400x 150мм, без фланца | AE6: 18689.83 | AF6: 13,083.07 | AG6: 16,951.00
B7: 300 | C7: 400 | D7: 200 | E7: IP67 | F7: 1 | G7: SE2005 | H7: =2*(B7*C7+C7*D7+B7*D7)/1000000 -> 0.52 | J7: =I7*$J$1 -> 0 | K7: =S7*$K$1 -> 9544.8972 | L7: =K7/0.75 -> 12726.53 | M7: =ROUND(L7,0) -> 12727 | P7: =O7*0.75 -> 0 | Q7: =P7/H7 -> 0 | R7: 19321.654 | S7: =R7*H7 -> 10047.26 | V7: 1011600 | W7: AE Шкаф, нерж.сталь с МП 380x300x210mm | X7: 206.09 | Y7: =X7*$Y$2 -> 14955.951 | Z7: 12,987.07 | AA7: 17,037.00
B8: 400 | C8: 300 | D8: 150 | E8: IP67 | F8: 1 | G8: SE2006 | H8: =2*(B8*C8+C8*D8+B8*D8)/1000000 -> 0.45 | J8: =I8*$J$1 -> 0 | K8: =S8*$K$1 -> 9298.125 | L8: =K8/0.75 -> 12397.5 | M8: =ROUND(L8,0) -> 12398 | N8: SES 40.30.15 | O8: 13197 | P8: =O8*0.75 -> 9897.75 | Q8: =P8/H8 -> 21995 | R8: 21750 | S8: =R8*H8 -> 9787.5 | T8: Корпус UC2 40.30.15 из нержавеющей стали IP66 USOLA | U8: 9900 | Y8: =X8*$Y$2 -> #VALUE! | AC8: R5CEB04311 | AD8: Навесной шкаф CE из нержавеющей стали (AISI 304), 400 x 300x 150мм, без фланца | AE8: 18748.7 | AF8: 13,124.28 | AG8: 17,004.00
B9: 400 | C9: 300 | D9: 200 | E9: IP67 | F9: 1 | G9: SE2007 | H9: =2*(B9*C9+C9*D9+B9*D9)/1000000 -> 0.52 | J9: =I9*$J$1 -> 0 | K9: =S9*$K$1 -> 9544.8972 | L9: =K9/0.75 -> 12726.53 | M9: =ROUND(L9,0) -> 12727 | P9: =O9*0.75 -> 0 | Q9: =P9/H9 -> 0 | R9: 19321.654 | S9: =R9*H9 -> 10047.26 | T9: Корпус UC2 40.30.20 из нержавеющей стали IP66 USOLA | U9: 10230 | V9: 1005600 | W9: AE Шкаф, нерж.сталь с МП 300x380x210mm | X9: 212.2 | Y9: =X9*$Y$2 -> 15399.354 | Z9: 14,273.02 | AA9: 17,651.00 | AC9: R5CEB04321 | AD9: Навесной шкаф CE из нержавеющей стали (AISI 304), 400 x 300x 200мм, без фланца | AE9: 21738.47 | AF9: 15,217.15 | AG9: 19,716.00
B10: 400 | C10: 400 | D10: 200 | E10: IP67 | F10: 1 | G10: SE2008 | H10: =2*(B10*C10+C10*D10+B10*D10)/1000000 -> 0.64 | J10: =I10*$J$1 -> 0 | K10: =S10*$K$1 -> 11198.362 | L10: =K10/0.75 -> 14931.15 | M10: =ROUND(L10,0) -> 14931 | N10: SES 40.40.21 | O10: 15717 | P10: =O10*0.75 -> 11787.75 | Q10: =P10/H10 -> 18418.359 | R10: 18418.359 | S10: =R10*H10 -> 11787.75 | T10: Корпус UC2 40.40.20 из нержавеющей стали IP66 USOLA | U10: 11770 | V10: 1006600 | W10: AE Шкаф, нерж.сталь с МП 380x380x210mm | X10: 233.54 | Y10: =X10*$Y$2 -> 16947.998 | Z10: 15,708.18 | AA10: 19,426.00 | AC10: R5CEB04421 | AD10: Навесной шкаф CE из нержавеющей стали (AISI 304), 400 x 400x 200мм, без фланца | AE10: 24290.12 | AF10: 17,003.33 | AG10: 22,030.00
B11: 400 | C11: 600 | D11: 200 | E11: IP67 | F11: 1 | G11: SE2009 | H11: =2*(B11*C11+C11*D11+B11*D11)/1000000 -> 0.88 | J11: =I11*$J$1 -> 0 | K11: =S11*$K$1 -> 13994.212 | L11: =K11/0.75 -> 18658.95 | M11: =ROUND(L11,0) -> 18659 | P11: =O11*0.75 -> 0 | Q11: =P11/H11 -> 0 | R11: 16739.489 | S11: =R11*H11 -> 14730.75 | T11: Корпус UC2 40.60.20 из нержавеющей стали IP66 USOLA | U11: 12980 | V11: 1009600 | W11: AE Шкаф, нерж.сталь с МП600x380x210mm | X11: 291.74 | Y11: =X11*$Y$2 -> 21171.572 | Z11: 19,622.89 | AA11: 24,267.00 | AC11: R5CEB04621 | AD11: Навесной шкаф CE из нержавеющей стали (AISI 304), 400 x 600x 200мм, без фланца | AE11: 28028.69 | AF11: 19,620.37 | AG11: 25,421.00
B12: 500 | C12: 300 | D12: 150 | E12: IP67 | F12: 2 | G12: SE2010 | H12: =2*(B12*C12+C12*D12+B12*D12)/1000000 -> 0.54 | J12: =I12*$J$1 -> 0 | K12: =S12*$K$1 -> 9728.3574 | L12: =K12/0.75 -> 12971.143 | M12: =ROUND(L12,0) -> 12971 | P12: =O12*0.75 -> 0 | Q12: =P12/H12 -> 0 | R12: 18963.66 | S12: =R12*H12 -> 10240.376 | Y12: =X12*$Y$2 -> 0 | AC12: R5CEB05311 | AD12: Навесной шкаф CE из нержавеющей стали (AISI 304), 500 x 300x 150мм, без фланца | AE12: 20366.02 | AF12: 14,256.42 | AG12: 18,471.00
B13: 500 | C13: 300 | D13: 200 | E13: IP67 | F13: 2 | G13: SE2011 | H13: =2*(B13*C13+C13*D13+B13*D13)/1000000 -> 0.62 | J13: =I13*$J$1 -> 0 | K13: =S13*$K$1 -> 11115.632 | L13: =K13/0.75 -> 14820.843 | M13: =ROUND(L13,0) -> 14821 | P13: =O13*0.75 -> 0 | Q13: =P13/H13 -> 0 | R13: 18872.041 | S13: =R13*H13 -> 11700.666 | Y13: =X13*$Y$2 -> 0 | AC13: R5CEB05321 | AD13: Навесной шкаф CE из нержавеющей стали (AISI 304), 500 x 300x 200мм, без фланца | AE13: 24177.61 | AF13: 16,924.56 | AG13: 21,928.00
B14: 500 | C14: 400 | D14: 200 | E14: IP67 | F14: 2 | G14: SE2012 | H14: =2*(B14*C14+C14*D14+B14*D14)/1000000 -> 0.76 | J14: =I14*$J$1 -> 0 | K14: =S14*$K$1 -> 13095.75 | L14: =K14/0.75 -> 17461 | M14: =ROUND(L14,0) -> 17461 | N14: SES 50.40.21 | O14: 18380 | P14: =O14*0.75 -> 13785 | Q14: =P14/H14 -> 18138.158 | R14: 18138.158 | S14: =R14*H14 -> 13785 | T14: Корпус UC2 50.40.20 из нержавеющей стали IP66 USOLA | U14: 13750 | V14: 1015600 | W14: AE Шкаф, нерж.сталь с МП 400x500x210mm | X14: 277.23 | Y14: =X14*$Y$2 -> 20118.581 | Z14: 18,647.08 | AA14: 23,060.00 | AC14: R5CEB05421 | AD14: Навесной шкаф CE из нержавеющей стали (AISI 304), 500 x 400x 200мм, без фланца | AE14: 26310.67 | AF14: 18,417.74 | AG14: 23,863.00
B15: 500 | C15: 500 | D15: 200 | E15: IP67 | F15: 2 | G15: SE2013 | H15: =2*(B15*C15+C15*D15+B15*D15)/1000000 -> 0.9 | J15: =I15*$J$1 -> 0 | K15: =S15*$K$1 -> 14710.275 | L15: =K15/0.75 -> 19613.7 | M15: =ROUND(L15,0) -> 19614 | N15: SES 50.50.21 | O15: 20646 | P15: =O15*0.75 -> 15484.5 | Q15: =P15/H15 -> 17205 | R15: 17205 | S15: =R15*H15 -> 15484.5 | T15: Корпус UC2 50.50.20 из нержавеющей стали IP66 USOLA | U15: 15510 | V15: 1007600 | W15: AE Шкаф, нерж.сталь с МП 500x500x210mm | X15: 306.78 | Y15: =X15*$Y$2 -> 22263.025 | Z15: 20,635.16 | AA15: 25,519.00 | AC15: R5CEB05521 | AD15: Навесной шкаф CE из нержавеющей стали (AISI 304), 500 x 500x 200мм, без фланца | AE15: 28436.78 | AF15: 19,906.03 | AG15: 25,791.00
B16: 500 | C16: 600 | D16: 200 | E16: IP67 | F16: 2 | G16: SE2014 | H16: =2*(B16*C16+C16*D16+B16*D16)/1000000 -> 1.04 | J16: =I16*$J$1 -> 0 | K16: =S16*$K$1 -> 17550.186 | L16: =K16/0.75 -> 23400.248 | M16: =ROUND(L16,0) -> 23400 | P16: =O16*0.75 -> 0 | Q16: =P16/H16 -> 0 | R16: 17763.347 | S16: =R16*H16 -> 18473.88 | Y16: =X16*$Y$2 -> 0
B17: 500 | C17: 400 | D17: 250 | E17: IP67 | F17: 2 | G17: SE2015 | H17: =2*(B17*C17+C17*D17+B17*D17)/1000000 -> 0.85 | J17: =I17*$J$1 -> 0 | K17: =S17*$K$1 -> 14859.281 | L17: =K17/0.75 -> 19812.374 | M17: =ROUND(L17,0) -> 19812 | P17: =O17*0.75 -> 0 | Q17: =P17/H17 -> 0 | R17: 18401.586 | S17: =R17*H17 -> 15641.348 | Y17: =X17*$Y$2 -> 0 | AC17: R5CEB05491 | AD17: Навесной шкаф CE из нержавеющей стали (AISI 304), 500 x 400x 250мм, без фланца | AE17: 29500.64 | AF17: 20,650.74 | AG17: 26,756.00
B18: 500 | C18: 500 | D18: 300 | E18: IP67 | F18: 2 | G18: SE2016 | H18: =2*(B18*C18+C18*D18+B18*D18)/1000000 -> 1.1 | J18: =I18*$J$1 -> 0 | K18: =S18*$K$1 -> 18599.178 | L18: =K18/0.75 -> 24798.905 | M18: =ROUND(L18,0) -> 24799 | P18: =O18*0.75 -> 0 | Q18: =P18/H18 -> 0 | R18: 17798.257 | S18: =R18*H18 -> 19578.083 | V18: 1013600 | W18: AE Шкаф, нерж.сталь с МП 500x500x300mm | X18: 360.72 | Y18: =X18*$Y$2 -> 26177.45 | Z18: 24,263.41 | AA18: 30,006.00
B19: 500 | C19: 600 | D19: 300 | E19: IP67 | F19: 2 | G19: SE2017 | H19: =2*(B19*C19+C19*D19+B19*D19)/1000000 -> 1.26 | J19: =I19*$J$1 -> 0 | K19: =S19*$K$1 -> 20917.879 | L19: =K19/0.75 -> 27890.505 | M19: =ROUND(L19,0) -> 27891 | P19: =O19*0.75 -> 0 | Q19: =P19/H19 -> 0 | R19: 17475.254 | S19: =R19*H19 -> 22018.82 | Y19: =X19*$Y$2 -> 0
B20: 600 | C20: 400 | D20: 200 | E20: IP67 | F20: 2 | G20: SE2018 | H20: =2*(B20*C20+C20*D20+B20*D20)/1000000 -> 0.88 | J20: =I20*$J$1 -> 0 | K20: =S20*$K$1 -> 13994.212 | L20: =K20/0.75 -> 18658.95 | M20: =ROUND(L20,0) -> 18659 | N20: SES 60.40.21 | O20: 19641 | P20: =O20*0.75 -> 14730.75 | Q20: =P20/H20 -> 16739.489 | R20: 16739.489 | S20: =R20*H20 -> 14730.75 | T20: Корпус UC2 60.40.20 из нержавеющей стали IP66 USOLA | U20: 14740 | V20: 1008600 | W20: AE Шкаф, нерж.сталь с МП 380x600x210mm | X20: 292.62 | Y20: =X20*$Y$2 -> 21235.433 | Z20: 19,682.19 | AA20: 24,341.00 | AC20: R5CEB06421 | AD20: Навесной шкаф CE из нержавеющей стали (AISI 304), 600 x 400x 200мм, без фланца | AE20: 28225.02 | AF20: 19,757.80 | AG20: 25,599.00
B21: 600 | C21: 500 | D21: 200 | E21: IP67 | F21: 2 | G21: SE2019 | H21: =2*(B21*C21+C21*D21+B21*D21)/1000000 -> 1.04 | J21: =I21*$J$1 -> 0 | K21: =S21*$K$1 -> 17550.186 | L21: =K21/0.75 -> 23400.248 | M21: =ROUND(L21,0) -> 23400 | P21: =O21*0.75 -> 0 | Q21: =P21/H21 -> 0 | R21: 17763.347 | S21: =R21*H21 -> 18473.88 | Y21: =X21*$Y$2 -> 0
B22: 600 | C22: 400 | D22: 250 | E22: IP67 | F22: 2 | G22: SE2020 | H22: =2*(B22*C22+C22*D22+B22*D22)/1000000 -> 0.98 | I22: 20028.054 | J22: =I22*$J$1 -> 26036.471 | K22: =S22*$K$1 -> 16783.814 | L22: =K22/0.75 -> 22378.418 | M22: =ROUND(L22,0) -> 22378 | P22: =O22*0.75 -> 0 | Q22: =P22/H22 -> 0 | R22: 18027.727 | S22: =R22*H22 -> 17667.172 | Y22: =X22*$Y$2 -> 0 | AC22: R5CEB06491 | AD22: Навесной шкаф CE из нержавеющей стали (AISI 304), 600 x 400x 250мм, без фланца | AE22: 31496.47 | AF22: 22,047.84 | AG22: 28,566.00
B23: 600 | C23: 600 | D23: 250 | E23: IP67 | F23: 2 | G23: SE2021 | H23: =2*(B23*C23+C23*D23+B23*D23)/1000000 -> 1.32 | J23: =I23*$J$1 -> 0 | K23: =S23*$K$1 -> 19860.938 | L23: =K23/0.75 -> 26481.25 | M23: =ROUND(L23,0) -> 26481 | N23: SES 60.60.25 | O23: 27875 | P23: =O23*0.75 -> 20906.25 | Q23: =P23/H23 -> 15838.068 | R23: 15838.068 | S23: =R23*H23 -> 20906.25 | T23: Корпус UC2 60.60.25 из нержавеющей стали IP66 USOLA | U23: 20900 | V23: 1010600 | W23: AE Шкаф, нерж.сталь с МП 600x600x210mm | X23: 375.24 | Y23: =X23*$Y$2 -> 27231.167 | Z23: 25,239.94 | AA23: 31,214.00 | AC23: R5CEB06691 | AD23: Навесной шкаф CE из нержавеющей стали (AISI 304), 600 x 600x 250мм, без фланца | AE23: 36638.32 | AF23: 25,647.18 | AG23: 33,230.00
B24: 600 | C24: 400 | D24: 400 | E24: IP67 | F24: 2 | G24: SE2022 | H24: =2*(B24*C24+C24*D24+B24*D24)/1000000 -> 1.28 | J24: =I24*$J$1 -> 0 | K24: =S24*$K$1 -> 21004.23 | L24: =K24/0.75 -> 28005.64 | M24: =ROUND(L24,0) -> 28006 | P24: =O24*0.75 -> 0 | Q24: =P24/H24 -> 0 | R24: 17273.215 | S24: =R24*H24 -> 22109.716 | Y24: =X24*$Y$2 -> 0 | AC24: R5CEB06441 | AD24: Навесной шкаф CE из нержавеющей стали (AISI 304), 600 x 400x 400мм, без фланца | AE24: 52433.47 | AF24: 36,703.95 | AG24: 47,556.00
B25: 600 | C25: 600 | D25: 400 | E25: IP67 | F25: 2 | G25: SE2023 | H25: =2*(B25*C25+C25*D25+B25*D25)/1000000 -> 1.68 | J25: =I25*$J$1 -> 0 | K25: =S25*$K$1 -> 26223.733 | L25: =K25/0.75 -> 34964.977 | M25: =ROUND(L25,0) -> 34965 | P25: =O25*0.75 -> 0 | Q25: =P25/H25 -> 0 | R25: 16430.91 | S25: =R25*H25 -> 27603.929 | Y25: =X25*$Y$2 -> 0 | AC25: R5CEB06641 | AD25: Навесной шкаф CE из нержавеющей стали (AISI 304), 600 x 600x 400мм, без фланца | AE25: 53373.94 | AF25: 37,362.29 | AG25: 48,408.00
B26: 700 | C26: 500 | D26: 200 | E26: IP67 | F26: 2 | G26: SE2024 | H26: =2*(B26*C26+C26*D26+B26*D26)/1000000 -> 1.18 | J26: =I26*$J$1 -> 0 | K26: =S26*$K$1 -> 19698.77 | L26: =K26/0.75 -> 26265.027 | M26: =ROUND(L26,0) -> 26265 | P26: =O26*0.75 -> 0 | Q26: =P26/H26 -> 0 | R26: 17572.498 | S26: =R26*H26 -> 20735.548 | Y26: =X26*$Y$2 -> 0 | AC26: R5CEB07521 | AD26: Навесной шкаф CE из нержавеющей стали (AISI 304), 700 x 500x 200мм, без фланца | AE26: 34129.82 | AF26: 23,891.22 | AG26: 30,955.00
B27: 700 | C27: 500 | D27: 250 | E27: IP67 | F27: 2 | G27: SE2025 | H27: =2*(B27*C27+C27*D27+B27*D27)/1000000 -> 1.3 | J27: =I27*$J$1 -> 0 | K27: =S27*$K$1 -> 19488.3 | L27: =K27/0.75 -> 25984.4 | M27: =ROUND(L27,0) -> 25984 | N27: SES 70.50.25 | O27: 27352 | P27: =O27*0.75 -> 20514 | Q27: =P27/H27 -> 15780 | R27: 15780 | S27: =R27*H27 -> 20514 | T27: Корпус UC2 70.50.25 из нержавеющей стали IP66 USOLA | U27: 20570 | Y27: =X27*$Y$2 -> 0 | AC27: R5CEB07591 | AD27: Навесной шкаф CE из нержавеющей стали (AISI 304), 700 x 500x 250мм, без фланца | AE27: 37672.09 | AF27: 26,370.84 | AG27: 34,167.00
B28: 800 | C28: 600 | D28: 200 | E28: IP67 | F28: 2 | G28: SE2026 | H28: =2*(B28*C28+C28*D28+B28*D28)/1000000 -> 1.52 | J28: =I28*$J$1 -> 0 | K28: =S28*$K$1 -> 24282.009 | L28: =K28/0.75 -> 32376.012 | M28: =ROUND(L28,0) -> 32376 | P28: =O28*0.75 -> 0 | Q28: =P28/H28 -> 0 | R28: 16815.795 | S28: =R28*H28 -> 25560.009 | V28: 1012600 | W28: AE Шкаф, нерж.сталь с МП 600x760x210mm | X28: 435.11 | Y28: =X28*$Y$2 -> 31575.933 | Z28: 29,267.54 | AA28: 36,195.00
B29: 800 | C29: 800 | D29: 200 | E29: IP67 | F29: 2 | G29: SE2027 | H29: =2*(B29*C29+C29*D29+B29*D29)/1000000 -> 1.92 | J29: =I29*$J$1 -> 0 | K29: =S29*$K$1 -> 29019.526 | L29: =K29/0.75 -> 38692.702 | M29: =ROUND(L29,0) -> 38693 | P29: =O29*0.75 -> 0 | Q29: =P29/H29 -> 0 | R29: 15909.828 | S29: =R29*H29 -> 30546.87 | Y29: =X29*$Y$2 -> 0
B30: 800 | C30: 600 | D30: 250 | E30: IP67 | F30: 2 | G30: SE2028 | H30: =2*(B30*C30+C30*D30+B30*D30)/1000000 -> 1.66 | J30: =I30*$J$1 -> 0 | K30: =S30*$K$1 -> 26004.606 | L30: =K30/0.75 -> 34672.808 | M30: =ROUND(L30,0) -> 34673 | P30: =O30*0.75 -> 0 | Q30: =P30/H30 -> 0 | R30: 16489.921 | S30: =R30*H30 -> 27373.269 | Y30: =X30*$Y$2 -> 0 | AC30: R5CEB08691 | AD30: Навесной шкаф CE из нержавеющей стали (AISI 304), 800 x 600x 250мм, без фланца | AE30: 43740.62 | AF30: 30,618.86 | AG30: 39,671.00
B31: 800 | C31: 600 | D31: 300 | E31: IP67 | F31: 2 | G31: SE2029 | H31: =2*(B31*C31+C31*D31+B31*D31)/1000000 -> 1.8 | J31: =I31*$J$1 -> 0 | K31: =S31*$K$1 -> 24984.525 | L31: =K31/0.75 -> 33312.7 | M31: =ROUND(L31,0) -> 33313 | N31: SES 80.60.30 | O31: 35066 | P31: =O31*0.75 -> 26299.5 | Q31: =P31/H31 -> 14610.833 | R31: 14610.833 | S31: =R31*H31 -> 26299.5 | T31: Корпус UC2 80.60.30 из нержавеющей стали IP66 USOLA | U31: 26400 | Y31: =X31*$Y$2 -> 0 | AC31: R5CEB08631 | AD31: Навесной шкаф CE из нержавеющей стали (AISI 304), 800 x 600x 300мм, без фланца | AE31: 47769.53 | AF31: 33,439.15 | AG31: 43,325.00
B32: 800 | C32: 800 | D32: 300 | E32: IP67 | F32: 2 | G32: SE2030 | H32: =2*(B32*C32+C32*D32+B32*D32)/1000000 -> 2.24 | J32: =I32*$J$1 -> 0 | K32: =S32*$K$1 -> 32228.003 | L32: =K32/0.75 -> 42970.67 | M32: =ROUND(L32,0) -> 42971 | P32: =O32*0.75 -> 0 | Q32: =P32/H32 -> 0 | R32: 15144.738 | S32: =R32*H32 -> 33924.213 | V32: 1014600 | W32: AE Шкаф, нерж.сталь с МП 760x760x300mm | X32: 620.19 | Y32: =X32*$Y$2 -> 45007.188 | Z32: 41,717.48 | AA32: 51,591.00 | AC32: R5CEB08831 | AD32: Навесной шкаф CE из нержавеющей стали (AISI 304), 800 x 800x 300мм, без фланца | AE32: 55054.74 | AF32: 38,538.87 | AG32: 49,933.00
B33: 800 | C33: 600 | D33: 400 | E33: IP67 | F33: 2 | G33: SE2031 | H33: =2*(B33*C33+C33*D33+B33*D33)/1000000 -> 2.08 | J33: =I33*$J$1 -> 0 | K33: =S33*$K$1 -> 30644.502 | L33: =K33/0.75 -> 40859.336 | M33: =ROUND(L33,0) -> 40859 | P33: =O33*0.75 -> 0 | Q33: =P33/H33 -> 0 | R33: 15508.351 | S33: =R33*H33 -> 32257.371 | T33: Корпус UC2 80.80.40 из нержавеющей стали IP66 USOLA | U33: 33000 | Y33: =X33*$Y$2 -> 0 | AC33: R5CEB08641 | AD33: Навесной шкаф CE из нержавеющей стали (AISI 304), 800 x 600x 400мм, без фланца | AE33: 67920.48 | AF33: 47,545.02 | AG33: 61,602.00
B34: 800 | C34: 800 | D34: 400 | E34: IP67 | F34: 2 | G34: SE2032 | H34: =2*(B34*C34+C34*D34+B34*D34)/1000000 -> 2.56 | J34: =I34*$J$1 -> 0 | K34: =S34*$K$1 -> 34984.066 | L34: =K34/0.75 -> 46645.421 | M34: =ROUND(L34,0) -> 46645 | P34: =O34*0.75 -> 0 | Q34: =P34/H34 -> 0 | R34: 14384.895 | S34: =R34*H34 -> 36825.332 | Y34: =X34*$Y$2 -> 0 | AC34: R5CEB08841 | AD34: Навесной шкаф CE из нержавеющей стали (AISI 304), 800 x 800x 400мм, без фланца | AE34: 77630.89 | AF34: 54,342.40 | AG34: 70,409.00
B35: 1000 | C35: 600 | D35: 250 | E35: IP66 | F35: 2 | G35: SE2033 | H35: =2*(B35*C35+C35*D35+B35*D35)/1000000 -> 2 | J35: =I35*$J$1 -> 0 | K35: =S35*$K$1 -> 29823.832 | L35: =K35/0.75 -> 39765.109 | M35: =ROUND(L35,0) -> 39765 | P35: =O35*0.75 -> 0 | Q35: =P35/H35 -> 0 | R35: 15696.754 | S35: =R35*H35 -> 31393.507 | Y35: =X35*$Y$2 -> 0 | AC35: R5CEB10691 | AD35: Навесной шкаф CE из нержавеющей стали (AISI 304), 1000 x 600 x 250мм, без фланца | AE35: 49511.53 | AF35: 34,658.56 | AG35: 44,905.00
B36: 1000 | C36: 600 | D36: 300 | E36: IP66 | F36: 2 | G36: SE2034 | H36: =2*(B36*C36+C36*D36+B36*D36)/1000000 -> 2.16 | J36: =I36*$J$1 -> 0 | K36: =S36*$K$1 -> 31439.358 | L36: =K36/0.75 -> 41919.144 | M36: =ROUND(L36,0) -> 41919 | P36: =O36*0.75 -> 0 | Q36: =P36/H36 -> 0 | R36: 15321.325 | S36: =R36*H36 -> 33094.061 | T36: Корпус UC2 100.60.30 из нержавеющей стали IP66 USOLA | U36: 33000 | Y36: =X36*$Y$2 -> 0 | AC36: R5CEB10631 | AD36: Навесной шкаф CE из нержавеющей стали (AISI 304), 1000 x 600 x 300мм, без фланца | AE36: 53679.97 | AF36: 37,576.51 | AG36: 48,686.00
B37: 1000 | C37: 800 | D37: 300 | E37: IP66 | F37: 2 | G37: SE2035 | H37: =2*(B37*C37+C37*D37+B37*D37)/1000000 -> 2.68 | J37: =I37*$J$1 -> 0 | K37: =S37*$K$1 -> 33845.175 | L37: =K37/0.75 -> 45126.9 | M37: =ROUND(L37,0) -> 45127 | N37: SES 100.80.30 | O37: 47502 | P37: =O37*0.75 -> 35626.5 | Q37: =P37/H37 -> 13293.47 | R37: 13293.47 | S37: =R37*H37 -> 35626.5 | T37: Корпус UC2 100.80.30 из нержавеющей стали IP66 USOLA | U37: 35750 | V37: 1016600 | W37: AE Шкаф,нерж.сталь с МП 800x1000x300mm | X37: 704.6 | Y37: =X37*$Y$2 -> 51132.822 | Z37: 47,394.55 | AA37: 58,612.00 | AC37: R5CEB10831 | AD37: Навесной шкаф CE из нержавеющей стали (AISI 304), 1000 x 800 x 300мм, без фланца | AE37: 66091.39 | AF37: 46,264.64 | AG37: 59,943.00
B38: 1000 | C38: 600 | D38: 400 | E38: IP66 | F38: 2 | G38: SE2036 | H38: =2*(B38*C38+C38*D38+B38*D38)/1000000 -> 2.48 | J38: =I38*$J$1 -> 0 | K38: =S38*$K$1 -> 34386.097 | L38: =K38/0.75 -> 45848.129 | M38: =ROUND(L38,0) -> 45848 | P38: =O38*0.75 -> 0 | Q38: =P38/H38 -> 0 | R38: 14595.118 | S38: =R38*H38 -> 36195.892 | Y38: =X38*$Y$2 -> 0 | AC38: R5CEB10641 | AD38: Навесной шкаф CE из нержавеющей стали (AISI 304), 1000 x 600 x 400мм, без фланца | AE38: 75363.41 | AF38: 52,755.15 | AG38: 68,352.00
B39: 1000 | C39: 800 | D39: 400 | E39: IP66 | F39: 2 | G39: SE2037 | H39: =2*(B39*C39+C39*D39+B39*D39)/1000000 -> 3.04 | J39: =I39*$J$1 -> 0 | K39: =S39*$K$1 -> 38456.402 | L39: =K39/0.75 -> 51275.203 | M39: =ROUND(L39,0) -> 51275 | P39: =O39*0.75 -> 0 | Q39: =P39/H39 -> 0 | R39: 13315.929 | S39: =R39*H39 -> 40480.423 | Y39: =X39*$Y$2 -> 0 | AC39: R5CEB10841 | AD39: Навесной шкаф CE из нержавеющей стали (AISI 304), 1000 x 800 x 400мм, без фланца | AE39: 86497.47 | AF39: 60,549.09 | AG39: 78,451.00
B40: 1200 | C40: 600 | D40: 200 | E40: IP66 | F40: 2 | G40: SE2038 | H40: =2*(B40*C40+C40*D40+B40*D40)/1000000 -> 2.16 | J40: =I40*$J$1 -> 0 | K40: =S40*$K$1 -> 31439.358 | L40: =K40/0.75 -> 41919.144 | M40: =ROUND(L40,0) -> 41919 | P40: =O40*0.75 -> 0 | Q40: =P40/H40 -> 0 | R40: 15321.325 | S40: =R40*H40 -> 33094.061 | Y40: =X40*$Y$2 -> 0
...

Sheet SE2100(нерж304)
I1: 514
B2: IPEX
B3: 300 | C3: 200 | D3: 150 | E3: IP67 | F3: 1 | G3: SЕ2101 | H3: ='SE2000 (нерж304)'!M3 -> 11026 | I3: =H3+$I$1 -> 11540
B4: 300 | C4: 250 | D4: 150 | E4: IP67 | F4: 1 | G4: SE2102 | H4: ='SE2000 (нерж304)'!M4 -> 8793 | I4: =H4+$I$1 -> 9307
B5: 300 | C5: 300 | D5: 150 | E5: IP67 | F5: 1 | G5: SE2103 | H5: ='SE2000 (нерж304)'!M5 -> 9164 | I5: =H5+$I$1 -> 9678
B6: 300 | C6: 400 | D6: 150 | E6: IP67 | F6: 1 | G6: SE2104 | H6: ='SE2000 (нерж304)'!M6 -> 12398 | I6: =H6+$I$1 -> 12912
B7: 300 | C7: 400 | D7: 200 | E7: IP67 | F7: 1 | G7: SE2105 | H7: ='SE2000 (нерж304)'!M7 -> 12727 | I7: =H7+$I$1 -> 13241
B8: 400 | C8: 300 | D8: 150 | E8: IP67 | F8: 1 | G8: SE2106 | H8: ='SE2000 (нерж304)'!M8 -> 12398 | I8: =H8+$I$1 -> 12912
B9: 400 | C9: 300 | D9: 200 | E9: IP67 | F9: 1 | G9: SE2107 | H9: ='SE2000 (нерж304)'!M9 -> 12727 | I9: =H9+$I$1 -> 13241
B10: 400 | C10: 400 | D10: 200 | E10: IP67 | F10: 1 | G10: SE2108 | H10: ='SE2000 (нерж304)'!M10 -> 14931 | I10: =H10+$I$1 -> 15445
B11: 400 | C11: 600 | D11: 200 | E11: IP67 | F11: 1 | G11: SE2109 | H11: ='SE2000 (нерж304)'!M11 -> 18659 | I11: =H11+$I$1 -> 19173
B12: 500 | C12: 300 | D12: 150 | E12: IP67 | F12: 2 | G12: SE2110 | H12: ='SE2000 (нерж304)'!M12 -> 12971 | I12: =H12+$I$1 -> 13485
B13: 500 | C13: 300 | D13: 200 | E13: IP67 | F13: 2 | G13: SE2111 | H13: ='SE2000 (нерж304)'!M13 -> 14821 | I13: =H13+$I$1 -> 15335
B14: 500 | C14: 400 | D14: 200 | E14: IP67 | F14: 2 | G14: SE2112 | H14: ='SE2000 (нерж304)'!M14 -> 17461 | I14: =H14+$I$1 -> 17975
... B46: 1400 | C46: 800 | D46: 300 | E46: IP66 | F46: 2 | G46: SE2144 | H46: ='SE2000 (нерж304)'!M46 -> 54580 | I46: =H46+$I$1 -> 55094

Sheet Напольные корпуса линейных шкаф
B1: IPEX | F1: Провенто | I1: УЗОЛА
B2: высота | C2: Ширина шкафа, мм. | D2: Глубина шкафа, мм. | E2: Артикул
B3: 1200 | C3: 300 | D3: 400 | E3: FE 1001
B4: 1200 | C4: 300 | D4: 500 | E4: FE 1002
B5: 1200 | C5: 300 | D5: 600 | E5: FE 1003
B6: 1200 | C6: 300 | D6: 800 | E6: FE 1004
B7: 1200 | C7: 300 | D7: 1000 | E7: FE 1005
B8: 1200 | C8: 400 | D8: 300 | E8: FE 1001
B9: 1200 | C9: 400 | D9: 400 | E9: FE 1006
B10: 1200 | C10: 400 | D10: 500 | E10: FE 1007
B11: 1200 | C11: 400 | D11: 600 | E11: FE 1008
B12: 1200 | C12: 400 | D12: 800 | E12: FE 1009
B13: 1200 | C13: 400 | D13: 1000 | E13: FE 1010
B14: 1200 | C14: 600 | D14: 300 | E14: FE 1003
B15: 1200 | C15: 600 | D15: 400 | E15: FE 1008
B16: 1200 | C16: 600 | D16: 500 | E16: FE 1011 | I16: U7705126050 | J16: Корпус LC2 120.60.50 IP55 USOLA | K16: 25145
B17: 1200 | C17: 600 | D17: 600 | E17: FE 1012
B18: 1200 | C18: 600 | D18: 800 | E18: FE 1013
B19: 1200 | C19: 600 | D19: 1000 | E19: FE 1014
B20: 1200 | C20: 800 | D20: 300 | E20: FE 1004
B21: 1200 | C21: 800 | D21: 400 | E21: FE 1009
B22: 1200 | C22: 800 | D22: 500 | E22: FE 1015 | I22: U7705128050 | J22: Корпус LC2 120.80.50 IP55 USOLA | K22: 27351
B23: 1200 | C23: 600 | D23: 600 | E23: FE 1012
B24: 1200 | C24: 800 | D24: 800 | E24: FE 1016
B25: 1200 | C25: 800 | D25: 1000 | E25: FE 1017
B26: 1200 | C26: 1000 | D26: 300 | E26: FE 1005
B27: 1200 | C27: 1000 | D27: 400 | E27: FE 1010
B28: 1200 | C28: 1000 | D28: 500 | E28: FE 1018
B29: 1200 | C29: 1000 | D29: 600 | E29: FE 1014
B30: 1200 | C30: 1000 | D30: 800 | E30: FE 1017
B31: 1200 | C31: 1000 | D31: 1000 | E31: FE 1019
B32: 1400 | C32: 300 | D32: 400 | E32: FE 1020
B33: 1400 | C33: 300 | D33: 500 | E33: FE 1021
B34: 1400 | C34: 300 | D34: 600 | E34: FE 1022
... B44: 1400 | C44: 600 | D44: 400 | E44: FE 1027
B45: 1400 | C45: 600 | D45: 500 | E45: FE 1030 | I45: U7705146050 | J45: Корпус LC2 140.60.50 IP55 USOLA | K45: 25805
B46: 1400 | C46: 600 | D46: 600 | E46: FE 1031
B47: 1400 | C47: 600 | D47: 800 | E47: FE 1032
B48: 1400 | C48: 600 | D48: 1000 | E48: FE 1033
B49: 1400 | C49: 800 | D49: 300 | E49: FE 1023
...

Sheet коробки соеденительные CS
B1: IPEX | J1: Провенто | L1: УЗОЛА | O1: Rittal | R1: 72.57
B2: А, мм. | C2: В, мм. | D2: С, мм. | E2: H, мм. | F2: К, мм. | G2: Степень защиты | H2: Кол-во клемм | I2: Артикул | O2: 1545500 | P2: EB Электрошкафчик 150x300x80mm RAL7035 | Q2: 43.09 | R2: =Q2*$R$1 -> 3127.0413
B3: 230 | C3: 150 | D3: 135 | E3: 153 | F3: 185 | G3: IP67 | H3: 1х26, 2хРЕ | I3: СS1001 | L3: U7521202015 | M3: Корпус UC2 20.20.15 IP66 USOLA | N3: 2060 | O3: 1546500 | P3: EB Электрошкафчик 200x200x80mm RAL7035 | Q3: 40.38 | R3: =Q3*$R$1 -> 2930.3766
B4: 260 | C4: 260 | D4: 150 | E4: 183 | F4: 295 | G4: IP67 | H4: 1х30 | I4: СS1002 | J4: MES 20.20.12 | K4: 2381 | L4: U7521203015 | M4: Корпус UC2 20.30.15 IP66 USOLA | N4: 2191 | O4: 1547500 | P4: EB Электрошкафчик 200x400x80mm RAL7035 | Q4: 52.58 | R4: =Q4*$R$1 -> 3815.7306
B5: 310 | C5: 310 | D5: 200 | E5: 233 | F5: 345 | G5: IP67 | H5: 1х32, 4хРЕ | I5: СS1003 | J5: MES 30.30.15 | K5: 3433 | L5: U7521303020 | M5: Корпус UC2 30.30.20 IP66 USOLA | N5: 2977 | O5: 1548500 | P5: EB Электрошкафчик 150x300x120mm RAL7035 | Q5: 43.06 | R5: =Q5*$R$1 -> 3124.8642
B6: 480 | C6: 480 | D6: 200 | E6: 403 | F6: 515 | G6: IP67 | H6: 1х66, 1х59, 5хРЕ | I6: СS1004 | J6: MES 50.50.21 | K6: 5625 | L6: U7521505020 | M6: Корпус UC2 50.50.20 IP66 USOLA | N6: 4829 | O6: 1549500 | P6: EB Электрошкафчик 200x200x120mm RAL7035 | Q6: 37.76 | R6: =Q6*$R$1 -> 2740.2432
O7: 1550500 | P7: EB Электрошкафчик 200x400x120mm RAL7035 | Q7: 51.14 | R7: =Q7*$R$1 -> 3711.2298
B8: 230 | C8: 150 | D8: 135 | E8: 153 | F8: 185 | G8: IP67 | H8: 1х26, 2хРЕ | I8: СS2001 | O8: 1551500 | P8: EB Электрошкафчик 150x150x80mm RAL7035 | Q8: 38.83 | R8: =Q8*$R$1 -> 2817.8931
B9: 260 | C9: 260 | D9: 150 | E9: 183 | F9: 295 | G9: IP67 | H9: 1х30 | I9: СS2002 | J9: SES 30.20.15 | K9: 10847 | L9: U7582302015 | M9: Корпус UC2 30.20.15 из нержавеющей стали IP66 USOLA | N9: 8690 | O9: 1552500 | P9: EB Электрошкафчик 200x300x80mm RAL7035 | Q9: 47.7 | R9: =Q9*$R$1 -> 3461.589
B10: 310 | C10: 310 | D10: 200 | E10: 233 | F10: 345 | G10: IP67 | H10: 1х32, 4хРЕ | I10: СS2003 | J10: SES 30.40.15 | K10: 12197 | L10: U7582304015 | M10: Корпус UC2 30.40.15 из нержавеющей стали IP66 USOLA | N10: 9790 | O10: 1553500 | P10: EB Электрошкафчик150x150x120мм RАL7035 | Q10: 39.96 | R10: =Q10*$R$1 -> 2899.8972
B11: 480 | C11: 480 | D11: 200 | E11: 403 | F11: 515 | G11: IP67 | H11: 1х66, 1х59, 5хРЕ | I11: СS2004 | J11: SES 50.50.21 | K11: 19296 | L11: U7582505020 | M11: Корпус UC2 50.50.20 из нержавеющей стали IP66 USOLA | N11: 15510 | O11: 1554500 | P11: EB Электрошкафчик 200x300x120mm RAL7035 | Q11: 42.96 | R11: =Q11*$R$1 -> 3117.6072
O12: 1555500 | P12: EB Электрошкафчик 300x300x120mm RAL7035 | Q12: 47.83 | R12: =Q12*$R$1 -> 3471.0231
B13: 120 | C13: 120 | D13: 80 | E13: - | F13: 155 | G13: IP67 | H13: 1х11 | I13: СS1101 | J13: MBS 12.12.06 | K13: 1140 | L13: U7541121206 | M13: Клеммная коробкаТВ 12.12.06 IP66 USOLA | N13: 924 | O13: 1556500 | P13: EB Электрошкафчик 300x400x120mm RAL7035 | Q13: 59.21 | R13: =Q13*$R$1 -> 4296.8697
B14: 150 | C14: 150 | D14: 90 | E14: 73 | F14: 185 | G14: IP67 | H14: 1х14 | I14: СS1102 | J14: MBS 15.15.08 | K14: 1385 | L14: U7541151512 | M14: Клеммная коробка ТВ 15.15.12 IP66 USOLA | N14: 1447 | O14: 1557500 | P14: EB Электрошкафчик 200x500x120mm RAL7035 | Q14: 59.6 | R14: =Q14*$R$1 -> 4325.172
